Workbook
Name _Fill: #REF!
Name Access: [1]Validation!$E$2:$E$223
Name AccessCircuit: [1]Validation!$C$2:$C$29
Name ACTION: #REF!
Name CoS: [1]Validation!$G$2:$G$47
Name Countries: [1]Validation!$A$2:$A$301
Name Document_array: {"Book1"}
Name DSLCheckService: [1]Validation!$H$2:$H$4
Name fds: {"Book1"}
Name Funtion1: 'Test case List'!#REF!
Name Login: 'Test case List'!#REF!
Name Ma_testcase_34: #REF!
Name Port: [1]Validation!$F$2:$F$40
Name QLDH_TDTT_41: #REF!
Name QLHD_CDHD_15: #REF!
Name QLHD_CNHD_34: #REF!
Name QLHD_GHD_34: #REF!
Name QLHD_HHD_13: #REF!
Name QLHD_KHD_6: #REF!
Name QLHD_TH_1: #REF!
Name QLHD_THD_34: #REF!
Name Status: '1. Cập nhật ttcn'!#REF!
Name Status: '10. Đăng nhập'!#REF!
Name Status: '2. Đăng ký ĐT'!#REF!
Name Status: '3. Đề xuất ĐT'!#REF!
Name Status: '4. Xem trạng thái đăng ký ĐT'!#REF!
Name Status: '5. Xem quy trình hướng dẫn '!#REF!
Name Status: '6. Nộp báo cáo tuần'!#REF!
Name Status: '7. Nộp BC cuối'!#REF!
Name Status: '8. Xem PB'!#REF!
Name Status: '9. Xem HĐBV'!#REF!
Name Status: #REF!
Name Tên_TestCase: #REF!
Name VancoProducts: [1]Validation!$B$2:$B$4

Sheet Cover
C2: TEST CASE
B4: Project Name | C4: Website Quản lý đồ án tốt nghiệp | F4: Creator | G4: ThanhVu
B5: Project Code | C5: DA3 | F5: Reviewer/Approver
B6: Document Code | C6: =C5&"_"&"XXX"&"_"&"vx.x" -> DA3_XXX_vx.x | F6: Issue Date
F7: Version
B10: Record of change
B11: Effective Date | C11: Version | D11: Change Item | E11: *A,D,M | F11: Change description | G11: Reference
B12: 46122 | D12: Cập nhật thông tin cá nhân | E12: A
B13: 46123 | D13: Đăng ký ĐT | E13: A
D14: Đề xuất ĐT | E14: A
B15: 46127 | D15: Xem quy trình hướng dẫn | E15: A
D16: Đăng nhập | E16: A
B17: 46133 | D17: Xem trạng thái đăng ký ĐT | E17: A

Sheet Test case List
D1: TEST CASE LIST
B3: Project Name | D3: =Cover!C4 -> Website Quản lý đồ án tốt nghiệp
B4: Project Code | D4: =Cover!C5 -> DA3
B5: Test Environment Setup Description | D5: •Trình duyệt: Chrome version 146.0.7680.76, Edge version 146.0.3856.59 •Thiết bị: CPU Intel Core i7, RAM 32GB •Hệ điều hành: Windows 11 Pro
B8: No | C8: Function Name | D8: Sheet Name | E8: Description | F8: Pre-Condition
B9: 1 | C9: Cập nhật thông tin cá nhân | D9: =HYPERLINK("#'1. Cập nhật ttcn'!H3","Cập nhật thông tin cá nhân") -> Cập nhật thông tin cá nhân
B10: 2 | C10: Đăng ký đề tài | D10: =HYPERLINK("#'2. Đăng ký ĐT'!A1","Đăng ký đề tài") -> Đăng ký đề tài
B11: 3 | C11: Đề xuất đề tài | D11: =HYPERLINK("#'3. Đề xuất ĐT'!A1","Đề xuất đề tài") -> Đề xuất đề tài
B12: 4 | C12: Xem trạng thái đăng ký đề tài | D12: =HYPERLINK("#'4. Xem trạng thái đăng ký ĐT'!A1","Xem trạng thái đăng ký đề tài") -> Xem trạng thái đăng ký đề tài
B13: 5 | C13: Xem quy trình hướng dẫn | D13: =HYPERLINK("#'5. Xem quy trình HD'!A1","Xem quy trình hướng dẫn") -> Xem quy trình hướng dẫn
B14: 6 | C14: Nộp báo cáo tuần | D14: =HYPERLINK("#'6. Nộp báo cáo tuần'!A1","Nộp báo cáo tuần") -> Nộp báo cáo tuần
B15: 7 | C15: Nộp báo cáo cuối | D15: =HYPERLINK("#'7. Nộp BC cuối'!A1","Nộp báo cáo cuối") -> Nộp báo cáo cuối
B16: 8 | C16: Xem thông tin phản biện | D16: =HYPERLINK("#'8. Xem PB'!A1","Xem thông tin phản biện") -> Xem thông tin phản biện
B17: 9 | C17: Xem thông tin hội đồng bảo vệ | D17: =HYPERLINK("#'10. Xem HĐBV'!A1","Xem thông tin hội đồng bảo vệ") -> Xem thông tin hội đồng bảo vệ
B18: 10 | C18: Đăng nhập | D18: =HYPERLINK("#'11. Đăng nhập'!A1","Đăng nhập") -> Đăng nhập

Sheet 1. Cập nhật ttcn
B2: Back to TestReport | C2: =HYPERLINK("#'Test case List'!A1","Test case List") -> Test case List | G2: Total | H2: =COUNTIF($A$10:$A$852, "TC*") -> 33
B3: Module Code | C3: Cập nhật thông tin cá nhân | G3: Pass | H3: =(COUNTIF(H10:H44,"Pass")) -> 8
B4: Tester | C4: Vu Vy Thanh | G4: Fail | H4: =(COUNTIF(H10:H45,"Fail")) -> 2
G5: Untest | H5: =(COUNTIF(H10:H46,"Untest")) -> 23
B6: Percent Complete: | C6: =ROUND((H3 / (H2-H6))*100,2)&"%" -> 24.24% | G6: N/A | H6: =(COUNTIF(H10:H47,"N/A")) -> 0
A8: Test case ID | B8: Test Case Name | C8: Pre-Condition | D8: Test Case Steps | E8: Test Data | F8: Expected Output | G8: Bug ID | H8: Actual Result | I8: Note
A9: Functional TC
A10: TC-S01-01 | B10: Cập nhật thành công toàn bộ thông tin | C10: - Đã đăng nhập - Trang Thông tin sinh viên | D10: 1. Điền đầy đủ các trường 2. Upload CV hợp lệ 3. Ấn Lưu thông tin | E10: Ngày sinh: 03/08/2005 Giới tính: Nữ Sđt: 0363627792 Email: vuvythanh0308@gmail.com CV: CV.pdf (<10MB) | F10: - Thông báo thành công - Thông tin hiển thị trong các field | H10: Fail
A11: TC-S01-02 | B11: Tên sinh viên để trống | C11: - Đã đăng nhập - Trang Thông tin sinh viên | D11: 1. Xóa trắng Tên sinh viên 2. Ấn Lưu thông tin | E11: Tên sinh viên: "" | F11: Nút Lưu thông tin bị disable | H11: Pass
A12: TC-S01-03 | B12: Tên sinh viên chỉ nhập ký tự trắng | C12: - Đã đăng nhập - Trang Thông tin sinh viên | D12: 1. Nhập Tên sinh viên 2. Ấn Lưu thông tin | E12: Tên sinh viên: " " | F12: Nút Lưu thông tin bị disable | H12: Fail
A13: TC-S01-04 | B13: Tên sinh viên chứa khoảng trắng đầu/cuối | C13: - Đã đăng nhập - Trang Thông tin sinh viên | D13: 1. Nhập tên có khoảng trắng đầu/cuối 2. Ấn Lưu thông tin | E13: Tên sinh viên: " Vy Thanh " | F13: Trim khoảng trắng -Thông báo lưu thành công | H13: Pass
A14: TC-S01-05 | B14: Ngày sinh sai định dạng | C14: - Đã đăng nhập - Trang Thông tin sinh viên | D14: 1. Nhập ngày sinh không hợp lệ 2. Ấn Lưu thông tin | E14: Ngày sinh: 32/13/2025 | F14: Không thể nhập giá trị không tồn tại | H14: Untest
A15: TC-S01-06 | B15: Ngày sinh là ngày hiện tại | C15: - Đã đăng nhập - Trang Thông tin sinh viên | D15: 1. Chọn đúng ngày hôm nay 2. Ấn Lưu thông tin | E15: Ngày sinh: [ngày hiện tại] | F15: Hệ thống báo lỗi: "Ngày sinh phải nhỏ hơn ngày hiện tại" | H15: Untest
A16: TC-S01-07 | B16: Ngày sinh là ngày tương lai | C16: - Đã đăng nhập - Trang Thông tin sinh viên | D16: 1. Chọn ngày sinh ở tương lai 2. Ấn Lưu thông tin | E16: Ngày sinh: 01/01/2030 | F16: Hệ thống báo lỗi: "Ngày sinh không hợp lệ" | H16: Untest
A17: TC-S01-08 | B17: SĐT 9 số | C17: - Đã đăng nhập - Trang Thông tin sinh viên | D17: 1. Nhập SĐT 9 số 2. Ấn Lưu thông tin | E17: SĐT: 123456789 | F17: - Báo lỗi: "Số điện thoại không đúng định dạng" - Nút Lưu disabled | H17: Untest
A18: TC-S01-09 | B18: SĐT 11 số | C18: - Đã đăng nhập - Trang Thông tin sinh viên | D18: 1. Nhập SĐT 11 số 2. Ấn Lưu thông tin | E18: SĐT: 12345678901 | F18: Báo lỗi: "Số điện thoại không đúng định dạng" | H18: Untest
A19: TC-S01-10 | B19: SĐT chứa chữ cái | C19: - Đã đăng nhập - Trang Thông tin sinh viên | D19: 1. Nhập SĐT có chữ 2. Ấn Lưu thông tin | E19: SĐT: 123abc4567 | F19: Báo lỗi hoặc không cho nhập ký tự chữ vào field SĐT | H19: Untest
A20: TC-S01-11 | B20: SĐT chứa ký tự đặc biệt | C20: - Đã đăng nhập - Trang Thông tin sinh viên | D20: 1. Nhập SĐT có ký tự đặc biệt 2. Ấn Lưu thông tin | E20: SĐT: 036-362-7792 | F20: Báo lỗi: "Số điện thoại không đúng định dạng" | H20: Untest
A21: TC-S01-12 | B21: SĐT 10 số toàn khoảng trắng | C21: - Đã đăng nhập - Trang Thông tin sinh viên | D21: 1. Nhập SĐT gồm 10 khoảng trắng 2. Ấn Lưu thông tin | E21: SĐT: " " (10 spaces) | F21: Báo lỗi: "Số điện thoại không đúng định dạng" | H21: Untest
... A32: TC-S01-23 | B32: Không upload CV – vẫn lưu thành công | C32: - Đã đăng nhập - Trang Thông tin sinh viên | D32: 1. Điền đầy đủ thông tin, bỏ trống CV 2. Ấn Lưu thông tin | E32: CV: null | F32: Lưu thành công, không báo lỗi | H32: Untest
A33: TC-S01-24 | B33: Sửa Mã sinh viên | C33: - Đã đăng nhập - Trang Thông tin sinh viên | D33: 1. Thử click/sửa trường Mã sinh viên 2. Ấn Lưu thông tin | F33: Trường Mã sinh viên bị disable | H33: Untest
A34: TC-S01-25 | B34: Cập nhật chỉ thông tin (không upload CV) | C34: - Đã đăng nhập - Trang Thông tin sinh viên - SV đã có CV cũ | D34: 2. Sửa Email hợp lệ, không thay CV 3. Ấn Lưu thông tin | E34: Email mới: newemail@gmail.com CV: giữ nguyên | F34: Lưu thành công, CV cũ không bị xóa, Email cập nhật đúng | H34: Untest
A35: TC-S01-26 | B35: SV A không thể xem/sửa thông tin SV B | C35: - Đã đăng nhập với tài khoản SV A, SV B có data sẵn - Trang Thông tin sinh viên | D35: 1. SV A cập nhật thông tin thành công 2. Kiểm tra dữ liệu SV B trong DB | F35: Dữ liệu SV B không bị thay đổi | H35: Untest
A36: TC-S01-27 | B36: Truy cập trang khi chưa đăng nhập | C36: Chưa đăng nhập | D36: 1. Truy cập vào URL Báo cáo kết quả ĐATN khi chưa đăng nhập 2. Quan sát | F36: - Redirect về trang Đăng nhập - Không hiển thị dữ liệu | H36: Pass
A37: UX/UI
A38: TC-S01-28 | B38: Load form thông tin cá nhân | C38: - Đã đăng nhập - Trang Thông tin sinh viên | D38: 1. Vào chức năng Thông tin sinh viên | F38: - Load đúng form - Hiển thị đầy đủ các field: Mã SV, Tên SV, Ngày sinh, Giới tính, SĐT, Email, CV | H38: Pass
A39: TC-S01-29 | B39: Hiển thị dữ liệu hiện tại từ DB | C39: - Đã đăng nhập - Trang Thông tin sinh viên - SV có data trong DB | D39: 1. Quan sát dữ liệu hiển thị | F39: Hiển thị đúng và đầy đủ dữ liệu hiện tại từ DB | H39: Pass
A40: TC-S01-30 | B40: Thông báo thành công hiển thị sau khi lưu | C40: - Đã đăng nhập - Trang Thông tin sinh viên | D40: 1. Điền thông tin hợp lệ 2. Ấn Lưu thông tin 3. Quan sát thông báo | F40: Hiển thị thông báo cập nhật thành công | H40: Pass
A41: TC-S01-31 | B41: Message lỗi hiển thị rõ ràng khi nhập sai | C41: - Đã đăng nhập - Trang Thông tin sinh viên | D41: 1. Nhập email sai format 2. Ấn Lưu thông tin 3. Quan sát message lỗi | E41: Email: abc@gmail | F41: Message lỗi hiển thị đúng vị trí , nội dung rõ ràng, dễ hiểu | H41: Pass
A42: TC-S01-32 | B42: Dropdown Giới tính hiển thị đúng options | C42: - Đã đăng nhập - Trang Thông tin sinh viên | D42: 1. Click dropdown Giới tính 2. Quan sát danh sách | F42: Dropdown hiển thị: Nam, Nữ, Khác | H42: Pass
A43: Exception
A44: TC-S01-33 | B44: Mất kết nối mạng trong quá trình cập nhật | C44: - Đã đăng nhập - Trang Thông tin sinh viên - Không có internet | D44: 1. Điền đầy đủ các trường 2. Ngắt kết nối mạng trong khi đang lưu 3. Quan sát kết quả | F44: Hệ thống hiển thị lỗi | H44: Untest

Sheet 2. Đăng ký ĐT
B2: Back to TestReport | C2: =HYPERLINK("#'Test case List'!A1","Test case List") -> Test case List | G2: Total | H2: =COUNTIF($A$10:$A$841, "TC*") -> 34
B3: Module Code | C3: Đăng ký ĐT | G3: Pass | H3: =(COUNTIF(H10:H29,"Pass")) -> 4
B4: Tester | C4: Vu Vy Thanh | G4: Fail | H4: =(COUNTIF(H10:H29,"Fail")) -> 0
G5: Untest | H5: =(COUNTIF(H10:H45,"Untest")) -> 20
B6: Percent Complete: | C6: =ROUND((H3 / (H2-H6))*100,2)&"%" -> 11.76% | G6: N/A | H6: =(COUNTIF(H10:H29,"N/A")) -> 0
A8: Test case ID | B8: Test Case Name | C8: Pre-Condition | D8: Test Case Steps | E8: Test Data | F8: Expected Output | G8: Bug ID | H8: Actual Result | I8: Note
A9: Functional TC
A10: TC-S02-01 | B10: Đăng ký đề tài thành công | C10: - Đã đăng nhập - Sinh viên chưa đăng ký / đề xuất đề tài - Đang trong thời gian cho phép đăng ký | D10: 1. Vào chức năng Đăng ký đề tài ĐATN 2. Chọn Mã bộ môn 3. Chọn Tên giảng viên 4. Hệ thống hiển thị danh sách đề tài 5. Chọn 1 đề tài còn slot 6. Nhấn nút Đăng ký đề tài 7. Quan sát kết quả | F10: - Thông báo thành công - Trạng thái: "Chờ Tên giảng viên xác nhận" - Số sinh viên đã đăng ký Tên giảng viên tăng thêm 1 | H10: Pass
A11: TC-S02-02 | B11: Tên giảng viên được chọn chưa có đề tài nào | C11: - Đã đăng nhập - Sinh viên chưa đăng ký / đề xuất đề tài - Đang trong thời gian cho phép đăng ký | D11: 1. Vào Đăng ký đề tài 2. Chọn Giảng viên chưa có đề tài 3. Quan sát danh sách đề tài | F11: - Danh sách đề tài trống - Hiển thị thông báo: "Giảng viên chưa có đề tài" | H11: Pass
A12: TC-S02-03 | B12: Tên giảng viên còn đúng 1 slot cuối | C12: - Đã đăng nhập - Sinh viên chưa đăng ký / đề xuất đề tài - Đang trong thời gian cho phép đăng ký | D12: 1. Chọn Giảng viên Nguyễn Văn Đ (còn 1 slot) 2. Chọn đề tài còn slot 3. Nhấn Đăng ký đề tài | F12: - Thông báo thành công - Số sinh viên của Giảng viên Nguyễn Văn Đ tăng lên 7 - Giảng viên Nguyễn Văn Đ không còn cho đăng ký thêm | H12: Untest
A13: TC-S02-04 | B13: Tên giảng viên đã đủ số sinh viên tối đa | C13: - Đã đăng nhập - Sinh viên chưa đăng ký / đề xuất đề tài - Đang trong thời gian cho phép đăng ký | D13: 1. Vào Đăng ký đề tài 2. Chọn Giảng viên Nguyễn Văn Đ (đã đủ số lượng) 3. Quan sát | F13: Danh sách đề tài của GVHD bị ẩn | H13: Untest
A14: TC-S02-05 | B14: Đề tài còn đúng 1 slot cuối | C14: - Đã đăng nhập - Sinh viên chưa đăng ký / đề xuất đề tài - Đang trong thời gian cho phép đăng ký | D14: 1. Chọn Tên giảng viên có đề tài Mã đề tài E1 2. Chọn Mã đề tài E1 3. Nhấn Đăng ký đề tài | F14: - Thông báo thành công - Trạng thái: "Chờ Tên giảng viên xác nhận" | H14: Untest
A15: TC-S02-06 | B15: Đề tài đã có sinh viên đăng ký đầy | C15: - Đã đăng nhập - Sinh viên chưa đăng ký / đề xuất đề tài - Đang trong thời gian cho phép đăng ký | D15: 1. Chọn Tên giảng viên có đề tài Mã đề tài Q1 2. Tìm kiếm / duyệt danh sách đề tài 3. Tìm đúng tên Mã đề tài Q1 | F15: - Đề tài không xuất hiện | H15: Pass | J15: M
A16: TC-S02-07 | B16: Tìm kiếm đúng tên đề tài đã đầy | C16: - Đã đăng nhập - Sinh viên chưa đăng ký / đề xuất đề tài - Đang trong thời gian cho phép đăng ký | D16: 1. Nhập đúng tên Mã đề tài Q1 vào ô Tên đề tài 2. Nhấn Tìm kiếm 3. Quan sát kết quả | F16: - Hiển thị: "Không tồn tại bản ghi nào." - Đề tài đầy không lộ ra qua tìm kiếm | H16: Untest
A17: TC-S02-08 | B17: Sinh viên đã đăng ký đề tài trước đó | C17: - Đã đăng nhập - Sinh viên đã đăng ký (đang chờ duyệt) - Đang trong thời gian cho phép đăng ký | D17: 1. Vào Đăng ký đề tài 2. Chọn Tên giảng viên, chọn đề tài khác 3. Nhấn Đăng ký đề tài | F17: - Hệ thống ẩn nút Đăng ký đề tài | H17: Pass
A18: TC-S02-09 | B18: Sinh viên đã đề xuất đề tài | C18: - Đã đăng nhập - Sinh viên đã đề xuất đề tài (đang chờ duyệt) - Trong thời gian đăng ký | D18: 1. Vào Đăng ký đề tài 2. Chọn Tên giảng viên, chọn đề tài 3. Nhấn Đăng ký đề tài | F18: - Hệ thống ẩn nút Đăng ký đề tài | H18: Untest
A19: TC-S02-10 | B19: Sinh viên bị từ chối trước đó | C19: - Đã đăng nhập - Đề tài/đề xuất trước đó bị từ chối - Trong thời gian đăng ký | D19: 1. Vào Đăng ký đề tài 2. Chọn Tên giảng viên, chọn đề tài còn slot 3. Nhấn Đăng ký đề tài | F19: - Hệ thống cho phép đăng ký - Đăng ký thành công - Trạng thái mới: "Chờ Giảng viên xác nhận" | H19: Untest
A20: TC-S02-11 | B20: Ngoài thời gian cho phép đăng ký | C20: - Đã đăng nhập - Sinh viên chưa có đề tài - Đã hết thời hạn đăng ký | D20: 1. Vào Đăng ký đề tài 2. Chọn Tên giảng viên, chọn đề tài 3. Nhấn Đăng ký đề tài | F20: - Hệ thống từ chối - Thông báo: "Đợt đăng ký đề tài đã kết thúc" | H20: Untest
A21: TC-S02-12 | B21: Tìm kiếm đề tài theo từ khóa – partial match | C21: - Đã đăng nhập - Sinh viên chưa đăng ký / đề xuất đề tài - Đang trong thời gian cho phép đăng ký | D21: 1. Vào Đăng ký đề tài 2. Nhập từ khóa vào ô Tên đề tài 3. Nhấn Tìm kiếm 4. Quan sát danh sách | E21: Từ khóa: "AI" | F21: - Hiển thị tất cả đề tài có chứa "AI" trong tên (còn slot) - Không hiển thị đề tài đã đầy | H21: Untest
A22: TC-S02-13 | B22: Tìm kiếm đề tài theo tên đầy đủ – full match | C22: - Đã đăng nhập - Sinh viên chưa đăng ký / đề xuất đề tài - Đang trong thời gian cho phép đăng ký | D22: 1. Nhập chính xác tên đề tài vào ô Tìm kiếm 2. Nhấn Tìm kiếm | E22: Tên đề tài: "Đề xuất mô hình đánh giá chất lượng phần mềm dựa trên ISO/IEC 25010 và dữ liệu kiểm thử thực nghiệm" | F22: Trả về đúng 1 đề tài khớp tên đầy đủ | H22: Untest
A23: TC-S02-14 | B23: Filter không khớp kết quả nào | C23: - Đã đăng nhập - Sinh viên chưa đăng ký / đề xuất đề tài - Đang trong thời gian cho phép đăng ký | D23: 1. Nhập tên đề tài không tồn tại 2. Nhấn Tìm kiếm | E23: Tên đề tài: "XYZXYZ_không_tồn_tại" | F23: Hiển thị: "Không tồn tại bản ghi nào." | H23: Untest
A24: TC-S02-15 | B24: Input tên đề tài đúng 250 ký tự | C24: - Đã đăng nhập - Sinh viên chưa đăng ký / đề xuất đề tài - Đang trong thời gian cho phép đăng ký | D24: 1. Nhập chuỗi 250 ký tự vào ô Tên đề tài 2. Nhấn Tìm kiếm | E24: Tên đề tài: chuỗi 250 ký tự | F24: - Không báo lỗi - Hiển thị kết quả tìm kiếm | H24: Untest
A25: TC-S02-16 | B25: Input tên đề tài 251 ký tự | C25: - Đã đăng nhập - Sinh viên chưa đăng ký / đề xuất đề tài - Đang trong thời gian cho phép đăng ký | D25: 1. Nhập chuỗi 251 ký tự vào ô Tên đề tài 2. Quan sát | E25: Tên đề tài: chuỗi 251 ký tự | F25: Báo lỗi "Tên đề tài không vượt quá 250 ký tự " | H25: Untest
A26: TC-S02-17 | B26: Tên đề tài để trống | C26: - Đã đăng nhập - Sinh viên chưa đăng ký / đề xuất đề tài - Đang trong thời gian cho phép đăng ký | D26: 1. Bỏ trống ô Tên đề tài 2. Nhấn Tìm kiếm | E26: Tên đề tài: "" | F26: Hiển thị tất cả đề tài còn slot theo Mã bộ môn và Tên giảng viên đã chọn | H26: Untest
A27: TC-S02-18 | B27: Tên đề tài chỉ chứa khoảng trắng | C27: Đã đăng nhập Sinh viên chưa đăng ký / đề xuất đề tài Đang trong thời gian cho phép đăng ký | D27: 1. Nhập khoảng trắng vào ô Tên đề tài 2. Nhấn Tìm kiếm | E27: Tên đề tài: " " | F27: Hiển thị tất cả đề tài còn slot theo Mã bộ môn và Tên giảng viên đã chọn | H27: Untest
A28: TC-S02-19 | B28: Dropdown Mã bộ môn mặc định đúng ngành của Sinh viên | C28: - Đã đăng nhập - Sinh viên thuộc ngành CNTT | D28: 1. Vào Đăng ký đề tài 2. Quan sát giá trị mặc định của dropdown Mã bộ môn | F28: - Dropdown Mã Mã bộ môn tự động chọn CNTT - Không cần Sinh viên tự chọn | H28: Untest
A29: TC-S02-20 | B29: 2 Sinh viên đăng ký cùng 1 đề tài cuối slot cùng lúc | C29: Sinh viên A và Sinh viên B cùng đăng nhập | D29: 1. Sinh viên A và Sinh viên B cùng mở trang đề tài 2. Cả 2 cùng nhấn Đăng ký đề tài gần như đồng thời | F29: - Chỉ đúng 1 sinh viên đăng ký thành công - Sinh viên còn lại nhận thông báo từ chối | H29: Untest
A30: TC-S02-21 | B30: Số Sinh viên đã đăng ký Tên giảng viên tăng đúng 1 sau khi đăng ký thành công | C30: - Đã đăng nhập - Sinh viên chưa đăng ký / đề xuất đề tài - Đang trong thời gian cho phép đăng ký | D30: 1. Sinh viên đăng ký đề tài của Giảng viên Nguyễn Văn Đ thành công 2. Kiểm tra lại số Sinh viên của Giảng viên Nguyễn Văn Đ | F30: Cột 'Số sinh viên đã đăng ký Tên giảng viên này' cập nhật thành 4 | H30: Untest
A31: TC-S02-22 | B31: Đăng ký Sinh viên A không ảnh hưởng slot của đề tài khác | C31: - Đã đăng nhập - Sinh viên chưa đăng ký / đề xuất đề tài - Đang trong thời gian cho phép đăng ký | D31: 1. Sinh viên A đăng ký Mã đề tài E1 | F31: Slot của Mã đề tài Q1 vẫn không thay đổi | H31: Untest
A32: TC-S02-23 | B32: Truy cập trang Đăng ký đề tài khi chưa đăng nhập | C32: Chưa đăng nhập | D32: 1. Truy cập trực tiếp URL trang Đăng ký đề tài 2. Quan sát | E32: URL: http://14.241.80.87:9993/graduation/graduation-student-register-project-topic | F32: - Redirect về trang đăng nhập - Không hiển thị dữ liệu đề tài | H32: Pass
A33: UX/UI
A34: TC-S02-24 | B34: Bảng đề tài hiển thị đủ 9 cột đúng tên | C34: Đã đăng nhập Có kết quả tìm kiếm đề tài | D34: 1. Chọn Tên giảng viên có đề tài 2. Quan sát tiêu đề bảng danh sách đề tài | F34: Bảng hiển thị đủ 9 cột: STT | Tên đề tài | Tên Tên giảng viên | Email | SĐT | Mô tả | Số Sinh viên đã ĐK Tên giảng viên này | Tác vụ | Đăng ký đề tài | H34: Pass
A35: TC-S02-25 | B35: Nút Đăng ký đề tài hiển thị đúng cho đề tài còn slot | C35: Đã đăng nhập Có đề tài còn slot | D35: 1. Chọn Tên giảng viên có đề tài còn slot 2. Quan sát cột Tác vụ / Đăng ký đề tài | F35: Nút Đăng ký đề tài hiển thị | H35: Pass
A36: TC-S02-26 | B36: Thông tin Tên giảng viên trong bảng hiển thị đầy đủ (Email, SĐT) | C36: Đã đăng nhập Chọn Tên giảng viên có đề tài | D36: 1. Chọn Tên giảng viên 2. Quan sát các cột Email và SĐT trong bảng | F36: Cột Email và SĐT hiển thị đúng thông tin của Giảng viên Nguyễn Văn Đ | H36: Pass
A37: TC-S02-27 | B37: Load danh sách Tên giảng viên từ dropdown | C37: Đã đăng nhập Vào trang Đăng ký đề tài | D37: 1. Click vào dropdown Tên giảng viên 2. Quan sát danh sách | F37: - Danh sách Tên giảng viên load đúng - Hiển thị đầy đủ tên Tên giảng viên thuộc Mã bộ môn đang chọn | H37: Pass
A38: TC-S02-28 | B38: Chọn Tên giảng viên | C38: Đã đăng nhập Giảng viên Nguyễn Văn Đ có 3 đề tài còn slot | D38: 1. Chọn Giảng viên Nguyễn Văn Đ từ dropdown 2. Quan sát bảng đề tài | F38: - Bảng chỉ hiển thị đề tài của Giảng viên Nguyễn Văn Đ - Không lẫn đề tài của Tên giảng viên khác | H38: Pass
A39: TC-S02-29 | B39: Dropdown Tên giảng viên chỉ hiển thị Tên giảng viên thuộc bộ môn đang chọn | C39: - Đã đăng nhập - Có Tên giảng viên thuộc Mã bộ môn CNTT và Mã bộ môn CNPM | D39: 1. Chọn Mã bộ môn = CNTT 2. Mở dropdown Tên Tên giảng viên 3. Quan sát danh sách | F39: - Dropdown hiển thị danh sách giảng viên thuộc ngành CNTT - Không hiển thị bên KHMT | H39: Pass
A40: TC-S02-30 | B40: Đổi Mã bộ môn | C40: - Đã đăng nhập - Đang chọn Mã bộ môn = CNTT, Tên giảng viên = Giảng viên Nguyễn Văn Đ | D40: 1. Đổi Mã bộ môn từ CNTT sang CNPM 2. Quan sát dropdown Tên giảng viên | F40: - Dropdown Tên giảng viên reload chỉ hiển thị giảng viên thuộc CNPM - Giảng viên Nguyễn Văn Đ bị reset | H40: Pass
A41: TC-S02-31 | B41: Thông báo đăng ký thành công hiển thị rõ ràng | C41: - Đã đăng nhập - Sinh viên chưa đăng ký / đề xuất đề tài - Đang trong thời gian cho phép đăng ký | D41: 1. Đăng ký đề tài hợp lệ thành công 2. Quan sát thông báo | F41: - Thông báo thành công hiển thị - Nội dung rõ ràng, trạng thái "Chờ Tên giảng viên xác nhận" được cập nhật | H41: Pass
A42: TC-S02-32 | B42: Load trang Đăng ký đề tài – hiển thị đầy đủ thành phần | C42: - Đã đăng nhập - Sinh viên chưa đăng ký / đề xuất đề tài - Đang trong thời gian cho phép đăng ký | D42: 1. Vào chức năng Đăng ký đề tài ĐATN 2. Quan sát giao diện tổng thể | F42: Hiển thị đầy đủ: - Dropdown Mã bộ môn - Dropdown Tên Tên giảng viên - Input Tên đề tài - Nút Tìm kiếm - Bảng danh sách đề tài | H42: Pass
...

Sheet 3. Đề xuất ĐT
B2: Back to TestReport | C2: =HYPERLINK("#'Test case List'!A1","Test case List") -> Test case List | G2: Total | H2: =COUNTIF($A$10:$A$843, "TC*") -> 33
B3: Module Code | C3: Đề xuất ĐT | G3: Pass | H3: =(COUNTIF(H10:H32,"Pass")) -> 0
B4: Tester | C4: Vu Vy Thanh | G4: Fail | H4: =(COUNTIF(H10:H32,"Fail")) -> 0
G5: Untest | H5: =(COUNTIF(H10:H45,"Untest")) -> 26
B6: Percent Complete: | C6: =ROUND((H3 / (H2-H6))*100,2)&"%" -> 0% | G6: N/A | H6: =(COUNTIF(H10:H32,"N/A")) -> 0
A8: Test case ID | B8: Test Case Name | C8: Pre-Condition | D8: Test Case Steps | E8: Test Data | F8: Expected Output | G8: Bug ID | H8: Actual Result | I8: Note
A9: Functional TC
A10: TC-S03-01 | B10: Đề xuất thành công – đầy đủ thông tin bắt buộc, có file PDF | C10: - Đã đăng nhập - SV chưa có đề tài nào - Đang trong thời gian cho phép đề xuất | D10: 1. Vào chức năng Đề xuất đề tài 2. Nhập Tên đề tài hợp lệ 3. Chọn Ngôn ngữ báo cáo 4. Nhập Mô tả đề tài 5. Chọn GVHD còn slot 6. Upload file PDF hợp lệ 7. Nhấn Gửi đề xuất | E10: Tên ĐT: "Kiểm thử tự động website QLĐATN" Ngôn ngữ: Tiếng Việt Mô tả: "Nghiên cứu và áp dụng..." GVHD: GV_A (còn slot) File: MoTa.pdf (5MB) | F10: - Gửi đề xuất thành công - Thông báo thành công - Mã đề tài được sinh tự động - Trạng thái: "Chờ GV xác nhận" | H10: Untest
A11: TC-S03-02 | B11: Đề xuất thành công – không upload file (file là tùy chọn) | C11: - Đã đăng nhập - SV chưa có đề tài nào - Đang trong thời gian cho phép đề xuất | D11: 1. Vào Đề xuất đề tài 2. Nhập đủ Tên đề tài, Mô tả, chọn GVHD 3. BỎ TRỐNG file mô tả 4. Nhấn Gửi đề xuất | E11: Tên ĐT: "Kiểm thử tự động" Mô tả: "..." GVHD: GV_A File: null | F11: - Gửi thành công - Không báo lỗi thiếu file - Trạng thái: "Chờ GV xác nhận" | H11: Untest
A12: TC-S03-03 | B12: Đề xuất thành công – Mô tả hợp lệ 500 ký tự | C12: - Đã đăng nhập - SV chưa có đề tài nào - Đang trong thời gian cho phép đề xuất | D12: 1. Nhập Tên đề tài hợp lệ 2. Nhập Mô tả 500 ký tự 3. Chọn GVHD 4. Nhấn Gửi đề xuất | E12: Mô tả: chuỗi 500 ký tự hợp lệ | F12: Gửi thành công, mô tả được lưu đầy đủ | H12: Untest
A13: TC-S03-04 | B13: Tên đề tài để trống | C13: - Đã đăng nhập - SV chưa có đề tài nào - Đang trong thời gian cho phép đề xuất | D13: 1. Vào Đề xuất đề tài 2. Bỏ trống Tên đề tài 3. Điền đủ các trường còn lại 4. Nhấn Gửi đề xuất | E13: Tên đề tài: "" | F13: Nút Gửi bị disabled HOẶC Báo lỗi: "Tên đề tài không được để trống" | H13: Untest
A14: TC-S03-05 | B14: Tên đề tài chỉ chứa khoảng trắng | C14: - Đã đăng nhập - SV chưa có đề tài nào - Đang trong thời gian cho phép đề xuất | D14: 1. Nhập khoảng trắng vào Tên đề tài 2. Điền đủ các trường còn lại 3. Nhấn Gửi đề xuất | E14: Tên đề tài: " " | F14: Trim khoảng trắng, báo lỗi: "Tên đề tài không được để trống" | H14: Untest
A15: TC-S03-06 | B15: Tên đề tài đúng 250 ký tự | C15: - Đã đăng nhập - SV chưa có đề tài nào - Đang trong thời gian cho phép đề xuất | D15: 1. Nhập chuỗi đúng 250 ký tự vào Tên đề tài 2. Điền đủ các trường còn lại 3. Nhấn Gửi đề xuất | E15: Tên đề tài: chuỗi 250 ký tự | F15: Hệ thống chấp nhận, gửi đề xuất thành công | H15: Untest
A16: TC-S03-07 | B16: Tên đề tài 251 ký tự | C16: - Đã đăng nhập - SV chưa có đề tài nào - Đang trong thời gian cho phép đề xuất | D16: 1. Nhập chuỗi 251 ký tự vào Tên đề tài 2. Quan sát | E16: Tên đề tài: chuỗi 251 ký tự | F16: Báo lỗi: "Tên đề tài không được vượt quá 250 ký tự" | H16: Untest
A17: TC-S03-08 | B17: Mô tả đề tài để trống | C17: - Đã đăng nhập - SV chưa có đề tài nào - Đang trong thời gian cho phép đề xuất | D17: 1. Nhập Tên đề tài hợp lệ 2. Bỏ trống Mô tả đề tài 3. Chọn GVHD 4. Nhấn Gửi đề xuất | E17: Mô tả: "" | F17: Nút Đồng ý bị disabled | H17: Untest
A18: TC-S03-09 | B18: Mô tả đề tài vượt 1000 ký tự | C18: - Đã đăng nhập - SV chưa có đề tài nào - Đang trong thời gian cho phép đề xuất | D18: 1. Nhập Mô tả 1001 ký tự 2. Nhấn Gửi đề xuất | E18: Mô tả: chuỗi 1001 ký tự | F18: Báo lỗi: "Mô tả không được vượt quá 1000 ký tự" | H18: Untest
A19: TC-S03-10 | B19: Không chọn GVHD | C19: - Đã đăng nhập - SV chưa có đề tài nào - Đang trong thời gian cho phép đề xuất | D19: 1. Nhập Tên đề tài và Mô tả hợp lệ 2. Bỏ qua không chọn GVHD 3. Nhấn Gửi đề xuất | F19: Nút Đồng ý bị disable | H19: Untest
A20: TC-S03-11 | B20: GVHD đã đủ số lượng SV | C20: - Đã đăng nhập - SV chưa có đề tài nào - Đang trong thời gian cho phép đề xuất | D20: 1. Điền đầy đủ thông tin hợp lệ 2. Chọn GVHD = GV_B (đã đủ slot) 3. Nhấn Gửi đề xuất | F20: Danh sách đề tài của GV bị ẩn | H20: Untest
A21: TC-S03-12 | B21: Upload file PDF hợp lệ | C21: - Đã đăng nhập - SV chưa có đề tài nào - Đang trong thời gian cho phép đề xuất | D21: 1. Điền đầy đủ thông tin 2. Upload file PDF < dung lượng giới hạn 3. Nhấn Gửi đề xuất | E21: File: MoTaDeTai.pdf, 3MB | F21: Upload thành công, file được lưu và liên kết với đề tài | H21: Untest
A22: TC-S03-13 | B22: Upload file sai định dạng (.docx) | C22: - Đã đăng nhập - SV chưa có đề tài nào - Đang trong thời gian cho phép đề xuất | D22: 1. Điền đầy đủ thông tin 2. Chọn file .docx | E22: File: MoTa.docx | F22: Báo lỗi: "Chỉ chấp nhận file định dạng PDF" | H22: Untest
A23: TC-S03-14 | B23: Upload file PDF vượt dung lượng giới hạn | C23: - Đã đăng nhập - SV chưa có đề tài nào - Đang trong thời gian cho phép đề xuất | D23: 1. Điền đầy đủ thông tin 2. Upload file PDF vượt dung lượng 3. Nhấn Gửi đề xuất | E23: File: MoTa_large.pdf, 31MB | F23: Báo lỗi: "File vượt quá dung lượng cho phép" Yêu cầu chọn lại file | H23: Untest
A24: TC-S03-15 | B24: Upload nhiều file cùng lúc | C24: - Đã đăng nhập - SV chưa có đề tài nào - Đang trong thời gian cho phép đề xuất | D24: 1. Điền đầy đủ thông tin 2. Thử chọn 2 file PDF cùng lúc 3. Quan sát | E24: File: MoTa1.pdf + MoTa2.pdf | F24: Hệ thống chỉ chấp nhận 1 file HOẶC báo lỗi: "Chỉ được upload 1 file" | H24: Untest
A25: TC-S03-16 | B25: Upload file PDF bị corrupt | C25: - Đã đăng nhập - SV chưa có đề tài nào - Đang trong thời gian cho phép đề xuất | D25: 1. Điền đầy đủ thông tin 2. Upload file PDF bị corrupt 3. Nhấn Gửi đề xuất | E25: File: Corrupt.pdf (nội dung lỗi) | F25: Báo lỗi phù hợp, không lưu file lỗi | H25: Untest
A26: TC-S03-17 | B26: SV đã có đề tài đang chờ duyệt | C26: - Đã đăng nhập - SV đã có đề tài ở trạng thái Chờ GV/TBM xác nhận - Trong thời gian đề xuất | D26: 1. Vào Đề xuất đề tài 2. Điền đầy đủ thông tin hợp lệ 3. Nhấn Gửi đề xuất | F26: Hệ thống từ chối Thông báo: "Bạn đã có đề tài đang được xét duyệt" | H26: Untest
A27: TC-S03-18 | B27: Ngoài thời gian cho phép đề xuất | C27: - Đã đăng nhập - SV chưa có đề tài - Đã hết thời hạn đề xuất | D27: 1. Vào Đề xuất đề tài 2. Điền đầy đủ thông tin 3. Nhấn Gửi đề xuất | F27: Hệ thống từ chối | H27: Untest
A28: TC-S03-19 | B28: Đề tài cũ đã bị từ chối | C28: - Đã đăng nhập - Đề tài trước đó đã bị GV/TBM từ chôis - Trong thời gian đề xuất | D28: 1. Vào Đề xuất đề tài 2. Điền đầy đủ thông tin hợp lệ 3. Nhấn Gửi đề xuất | F28: - Hệ thống cho phép đề xuất đề tài mới - Gửi thành công - Trạng thái mới: "Chờ GV xác nhận" | H28: Untest
A29: TC-S03-20 | B29: SV có đề tài đã được duyệt | C29: - Đã đăng nhập - Đề tài đã được duyệt hoàn toàn | D29: 1. Vào Đề xuất đề tài 2. Điền thông tin và Gửi | F29: - Hệ thống từ chối - Thông báo phù hợp | H29: Untest
A30: TC-S03-21 | B30: Thiếu cả Tên đề tài lẫn GVHD | C30: - Đã đăng nhập - SV chưa có đề tài nào - Đang trong thời gian cho phép đề xuất | D30: 1. Bỏ trống Tên đề tài 2. Không chọn GVHD 3. Nhập Mô tả hợp lệ 4. Nhấn Gửi đề xuất | F30: Hiển thị đồng thời 2 lỗi tương ứng: - Lỗi Tên đề tài - Lỗi GVHD | H30: Untest
A31: TC-S03-22 | B31: Thiếu Mô tả và thiếu file | C31: - Đã đăng nhập - SV chưa có đề tài nào - Đang trong thời gian cho phép đề xuất | D31: 1. Nhập Tên đề tài hợp lệ 2. Chọn GVHD 3. Bỏ trống Mô tả 4. Không upload file 5. Nhấn Gửi đề xuất | E31: Mô tả: rỗng File: null | F31: Hệ thống vẫn chấp nhận đề tài | H31: Untest
A32: TC-S03-23 | B32: Submit nhiều lần | C32: - Đã đăng nhập - SV chưa có đề tài nào - Đang trong thời gian cho phép đề xuất | D32: 1. Điền đầy đủ thông tin hợp lệ 2. Click nút Gửi đề xuất 2 lần liên tiếp nhanh 3. Kiểm tra DB | F32: - Chỉ tạo 1 đề tài trong DB - Nút Gửi disabled sau click đầu | H32: Untest
A33: TC-S03-24 | B33: Refresh trang khi đang submit | C33: - Đã đăng nhập - SV chưa có đề tài nào - Đang trong thời gian cho phép đề xuất | D33: 1. Điền đầy đủ thông tin 2. Nhấn Gửi đề xuất 3. Ngay lập tức nhấn F5 (refresh) 4. Kiểm tra DB | F33: 1 đề tài được lưu | H33: Untest
A34: TC-S03-25 | B34: Đề xuất của SV A không ảnh hưởng dữ liệu SV B | C34: SV A và SV B đều có tài khoản hợp lệ | D34: 1. SV A gửi đề xuất thành công 2. Kiểm tra dữ liệu đề xuất của SV B trong DB | F34: Dữ liệu đề xuất của SV B không bị thay đổi | H34: Untest
A35: TC-S03-26 | B35: Truy cập trang đề xuất khi chưa đăng nhập | C35: Chưa đăng nhập | D35: 1. Truy cập trực tiếp URL trang Đề xuất đề tài 2. Quan sát kết quả | E35: URL: http://14.241.80.87:9993/graduation/graduation-student-register-project-topic | F35: - Redirect về trang đăng nhập - Không hiển thị form | H35: Pass
A36: UX/UI
A37: TC-S03-27 | B37: Load form đề xuất – hiển thị đúng và đầy đủ | C37: - Đã đăng nhập - SV chưa có đề tài | D37: 1. Vào chức năng Đề xuất đề tài 2. Quan sát giao diện | F37: Form hiển thị đầy đủ các trường: - Tên đề tài - Ngôn ngữ báo cáo - Mô tả đề tài - Chọn GVHD - Upload file - Nút Gửi đề xuất | H37: Pass
A38: TC-S03-28 | B38: Ngôn ngữ báo cáo có giá trị mặc định | C38: - Đã đăng nhập - Vừa mở form đề xuất | D38: 1. Vào form Đề xuất đề tài 2. Quan sát trường Ngôn ngữ báo cáo | F38: Ngôn ngữ mặc định chọn: Báo cáo tiếng Việt, bảo vệ tiếng Việt | H38: Pass
A39: TC-S03-29 | B39: Thông báo thành công hiển thị rõ ràng sau khi gửi | C39: - Đã đăng nhập - Đã submit hợp lệ | D39: 1. Điền thông tin hợp lệ 2. Nhấn Gửi đề xuất 3. Quan sát thông báo | F39: - Thông báo thành công hiển thị - Nội dung rõ ràng: xác nhận đã gửi đề xuất thành công | H39: Pass
A40: TC-S03-30 | B40: Thông báo lỗi hiển thị đúng vị trí – dưới field bị lỗi | C40: Đã đăng nhập | D40: 1. Bỏ trống Tên đề tài 2. Nhấn Gửi đề xuất 3. Quan sát vị trí message lỗi | E40: Tên đề tài: "" | F40: - Message lỗi hiển thị ngay dưới field Tên đề tài - Nội dung rõ ràng, không chỉ hiện toast chung chung | H40: Pass
A41: TC-S03-31 | B41: Nút Gửi đề xuất bị disabled khi form có lỗi | C41: - Đã đăng nhập - Form đang có trường bắt buộc rỗng | D41: 1. Mở form Đề xuất đề tài 2. Không điền Tên đề tài 3. Quan sát nút Gửi đề xuất | E41: Tên ĐT: "" | F41: Nút Gửi đề xuất bị disabled, không thể click khi form chưa hợp lệ | H41: Pass
A42: TC-S03-32 | B42: UI không vỡ khi resize màn hình | C42: - Đã đăng nhập - Form đề xuất đang mở | D42: 1. Mở form Đề xuất đề tài 2. Resize cửa sổ trình duyệt về chiều rộng nhỏ (tablet ~768px) 3. Quan sát layout | F42: - Form không bị vỡ layout - Các field vẫn hiển thị đầy đủ và sử dụng được - Không có element bị tràn/ẩn | H42: Pass
...

Sheet 4. Xem trạng thái đăng ký ĐT
B2: Back to TestReport | C2: =HYPERLINK("#'Test case List'!A1","Test case List") -> Test case List | G2: Total | H2: =COUNTIF($A$10:$A$840, "TC*") -> 31
B3: Module Code | C3: Xem trạng thái đăng ký ĐT | G3: Pass | H3: =(COUNTIF(H10:H28,"Pass")) -> 3
B4: Tester | C4: Vu Vy Thanh | G4: Fail | H4: =(COUNTIF(H10:H28,"Fail")) -> 0
G5: Untest | H5: =(COUNTIF(H10:H45,"Untest")) -> 23
B6: Percent Complete: | C6: =ROUND((H3 / (H2-H6))*100,2)&"%" -> 9.68% | G6: N/A | H6: =(COUNTIF(H10:H28,"N/A")) -> 0
A8: Test case ID | B8: Test Case Name | C8: Pre-Condition | D8: Test Case Steps | E8: Test Data | F8: Expected Output | G8: Bug ID | H8: Actual Result | I8: Note
A9: Functional TC
A10: TC-S04-01 | B10: Tìm kiếm theo tên đề tài – partial match | C10: - Đã đăng nhập - SV đã đăng ký đề tài - Danh sách có đề tài chứa cụm từ "kiểm thử" | D10: 1. Vào Đăng ký đề tài tốt nghiệp 2. Nhập một phần tên đề tài vào ô Tên đề tài 3. Nhấn Tìm kiếm 4. Quan sát kết quả | E10: Tên đề tài: "kiểm thử" | F10: - Hiển thị đúng các đề tài chứa chuỗi "Kiểm thử" - Cột Trạng thái hiển thị đúng trạng thái hiện tại của đề tài SV đã đăng ký | H10: Pass
A11: TC-S04-02 | B11: Tìm kiếm theo tên đề tài – full match | C11: - Đã đăng nhập - SV đã đăng ký đề tài - Danh sách có đề tài "Xây dựng quy trình kiểm thử bảo mật tự động tích hợp trong mô hình DevSecOps" | D11: 1. Nhập toàn bộ tên đề tài chính xác 2. Nhấn Tìm kiếm 3. Quan sát kết quả | E11: Tên đề tài: "Xây dựng quy trình kiểm thử bảo mật tự động tích hợp trong mô hình DevSecOps " | F11: Hiển thị đúng 1 đề tài khớp toàn bộ tên | H11: Pass
A12: TC-S04-03 | B12: Tìm kiếm theo Tên giảng viên | C12: - Đã đăng nhập - SV đã đăng ký đề tài - Danh sách có GV "Nguyễn Văn Đ" | D12: 1. Chọn Tên giảng viên "Nguyễn Văn Đ" từ dropdown 2. Nhấn Tìm kiếm 3. Quan sát kết quả | E12: Tên GV: Nguyễn Văn Đ | F12: - Hiển thị tất cả đề tài của GV Nguyễn Văn Đ - Trạng thái đề tài SV đã đăng ký hiển thị đúng | H12: Pass
A13: TC-S04-04 | B13: Tìm kiếm kết hợp Mã bộ môn + Tên giảng viên | C13: - Đã đăng nhập - SV đã đăng ký đề tài - Danh sách có dữ liệu nhiều bộ môn, nhiều GV | D13: 1. Chọn Mã bộ môn = Công nghệ phần mềm 2. Chọn Tên GV "Nguyễn Văn Đ" 3. Nhấn Tìm kiếm | E13: Mã Mã bộ môn: Công nghệ phần mềm Tên GV: Nguyễn Văn Đ | F13: - Chỉ hiển thị đề tài của GV Nguyễn Văn Đ thuộc Mã bộ môn Công nghệ phần mềm - Không lẫn GV khác hoặc Mã bộ môn khác | H13: Untest
A14: TC-S04-05 | B14: Tìm kiếm kết hợp Mã bộ môn + Tên đề tài | C14: - Đã đăng nhập - SV đã đăng ký đề tài | D14: 1. Chọn Mã Mã bộ môn = Công nghệ phần mềm 2. Nhập Tên đề tài = "Kiểm thử" 3. Nhấn Tìm kiếm | E14: Mã Mã bộ môn: Công nghệ phần mềm Tên đề tài: "Kiểm thử" | F14: Chỉ hiển thị đề tài chứa "Kiểm thử" thuộc Mã bộ môn Công nghệ phần mềm | H14: Untest
A15: TC-S04-06 | B15: Tìm kiếm kết hợp Tên giảng viên + Tên đề tài | C15: - Đã đăng nhập - SV đã đăng ký đề tài | D15: 1. Chọn Tên GV = "Nguyễn Văn Đ" 2. Nhập Tên đề tài = "Kiểm thử" 3. Nhấn Tìm kiếm | E15: Tên GV: Nguyễn Văn Đ Tên đề tài: "Kiểm thử" | F15: Chỉ hiển thị đề tài chứa "Kiểm thử" của GV Nguyễn Văn Đ | H15: Untest
A16: TC-S04-07 | B16: Tìm kiếm kết hợp cả 3 tiêu chí: Mã bộ môn + GV + Tên đề tài | C16: - Đã đăng nhập - SV đã đăng ký đề tài | D16: 1. Chọn Mã Mã bộ môn = Công nghệ phần mềm 2. Chọn Tên GV = "Nguyễn Văn Đ" 3. Nhập Tên đề tài = "Kiểm thử" 4. Nhấn Tìm kiếm | E16: Mã Mã bộ môn: Công nghệ phần mềm Tên GV: Nguyễn Văn Đ Tên đề tài: "Kiểm thử" | F16: Kết quả là giao của 3 tiêu chí – chỉ hiển thị đề tài thỏa cả 3 điều kiện | H16: Untest
A17: TC-S04-08 | B17: Tìm kiếm không có kết quả khớp | C17: - Đã đăng nhập - SV đã đăng ký đề tài | D17: 1. Nhập tên đề tài không tồn tại trong Danh sách 2. Nhấn Tìm kiếm 3. Quan sát kết quả | E17: Tên đề tài: "XYZXYZXYZ_không_tồn_tại" | F17: Hiển thị: "Không tồn tại bản ghi nào." | H17: Untest
A18: TC-S04-09 | B18: Tìm kiếm kết hợp filter không có kết quả khớp | C18: - Đã đăng nhập - SV đã đăng ký đề tài | D18: 1. Chọn Mã bộ môn không thuộc ngành SV 2. Nhập tên đề tài 3. Nhấn Tìm kiếm | E18: Mã bộ môn: KHMT Tên đề tài: "Kiểm thử" | F18: Hiển thị: "Không tồn tại bản ghi nào." | H18: Untest
A19: TC-S04-10 | B19: Tên đề tài để trống | C19: - Đã đăng nhập - SV đã đăng ký đề tài | D19: 1. Bỏ trống Tên đề tài 2. Nhấn Tìm kiếm 3. Quan sát kết quả | E19: Tên đề tài: "" | F19: Hệ thống hiển thị toàn bộ đề tài theo Mã bộ môn và GV đã chọn | H19: Untest
A20: TC-S04-11 | B20: Tên đề tài chỉ chứa khoảng trắng | C20: - Đã đăng nhập - SV đã đăng ký đề tài | D20: 1. Nhập khoảng trắng vào ô Tên đề tài 2. Nhấn Tìm kiếm | E20: Tên đề tài: " " | F20: Hệ thống hiển thị toàn bộ đề tài theo Mã bộ môn và GV đã chọn | H20: Untest
A21: TC-S04-12 | B21: Tên đề tài nhập đúng 250 ký tự | C21: - Đã đăng nhập - SV đã đăng ký đề tài | D21: 1. Nhập chuỗi 250 ký tự vào Tên đề tài 2. Nhấn Tìm kiếm | E21: Tên đề tài: chuỗi 250 ký tự | F21: Hệ thống hiển thị kết quả tìm kiếm | H21: Untest
A22: TC-S04-13 | B22: Tên đề tài nhập 251 ký tự | C22: - Đã đăng nhập - SV đã đăng ký đề tài | D22: 1. Nhập chuỗi 251 ký tự vào Tên đề tài 2. Quan sát | E22: Tên đề tài: chuỗi 251 ký tự | F22: Báo lỗi: "Độ dài không quá 250 ký tự" | H22: Untest
A23: TC-S04-14 | B23: Mã bộ môn mặc định đúng ngành học của SV | C23: - Đã đăng nhập - SV thuộc ngành Công nghệ phần mềm | D23: 1. Vào Đăng ký đề tài tốt nghiệp 2. Quan sát giá trị mặc định của dropdown Mã bộ môn | F23: - Dropdown Mã bộ môn tự động chọn Công nghệ phần mềm - Không cần SV tự chọn | H23: Untest
A24: TC-S04-15 | B24: Dropdown Tên GV hiển thị đúng danh sách theo Mã bộ môn đã chọn | C24: - Đã đăng nhập - Danh sách có GV thuộc Mã bộ môn Công nghệ phần mềm và Mã bộ môn Công nghệ thông tin | D24: 1. Chọn Mã bộ môn Công nghệ phần mềm 2. Mở dropdown Tên GV 3. Quan sát danh sách | F24: - Dropdown GV chỉ hiển thị danh sách Giảng viên ngành Công nghệ phần mềm - Không hiển thị giảng viên ngành Hệ thống thông tin | H24: Untest
A25: TC-S04-16 | B25: Đổi Mã bộ môn | C25: - Đã đăng nhập - Dropdown Mã bộ môn đang chọn Công nghệ phần mềm | D25: 1. Đổi Mã bộ môn từ Công nghệ phần mềm sang Hệ thống thông tin 2. Quan sát dropdown GV | F25: Dropdown GV reload và chỉ hiển thị GV thuộc Mã bộ môn Hệ thống thông tin | H25: Untest
A26: TC-S04-17 | B26: GVHD hiển thị thông tin số SV đã đăng ký trong bảng | C26: - Đã đăng nhập - GIảng viên Nguyễn Văn Đ có 3 SV đã đăng ký | D26: 1. Tìm kiếm đề tài của GIảng viên Nguyễn Văn Đ 2. Quan sát cột "Số lượng SV đã đăng ký GV này" | F26: Giao diện hiển thị đúng | H26: Untest
A27: TC-S04-18 | B27: GVHD đã đủ số SV tối đa – hiển thị đúng trong cột Số lượng | C27: - Đã đăng nhập - Giảng viên Nguyễn Văn Đ đã đủ số lượng SV đăng ký | D27: 1. Tìm kiếm đề tài của GIảng viên Nguyễn Văn Đ 2. Quan sát cột Số lượng SV và cột Tác vụ | F27: - Cột Số lượng hiển thị đúng - Nút đăng ký bị disabled hoặc ẩn | H27: Untest
A28: TC-S04-19 | B28: Trạng thái "Chờ GV xác nhận" hiển thị đúng | C28: - Đã đăng nhập - SV đã đăng ký đề tài, GV chưa duyệt | D28: 1. Vào Đăng ký đề tài tốt nghiệp 2. Tìm kiếm đề tài đã đăng ký 3. Quan sát cột Trạng thái | F28: Cột Trạng thái hiển thị đúng label: "Chờ GV xác nhận" | H28: Untest
A29: TC-S04-20 | B29: Trạng thái "Chờ TBM xác nhận" hiển thị đúng | C29: - Đã đăng nhập - SV đã đăng ký, GV đã duyệt, TBM chưa duyệt | D29: 1. Tìm kiếm đề tài đã đăng ký 2. Quan sát cột Trạng thái | F29: Cột Trạng thái hiển thị đúng label: "Chờ TBM xác nhận" | H29: Untest
A30: TC-S04-21 | B30: Trạng thái "Đã được duyệt" hiển thị đúng | C30: - Đã đăng nhập - Đề tài đã được GV và TBM duyệt | D30: 1. Tìm kiếm đề tài đã đăng ký 2. Quan sát cột Trạng thái | F30: Cột Trạng thái hiển thị: "Đã được duyệt" Không còn nút đăng ký lại | H30: Untest
A31: TC-S04-22 | B31: Trạng thái "Từ chối" – SV có thể đăng ký đề tài mới | C31: - Đã đăng nhập - Đề tài bị GV hoặc TBM từ chối | D31: 1. Tìm kiếm đề tài bị từ chối 2. Quan sát Trạng thái và Tác vụ 3. Thử đăng ký đề tài mới | F31: - Nút Đăng ký hiển thị lại - SV được phép đăng ký đề tài khác | H31: Untest
A32: TC-S04-23 | B32: Trạng thái cập nhật đúng sau khi GV duyệt | C32: - Đã đăng nhập - SV vừa được GV duyệt đề tài | D32: 1. Trước khi GV duyệt: xem trạng thái = "Chờ GV xác nhận" 2. GV duyệt đề tài 3. SV refresh trang hoặc chờ realtime update 4. Quan sát lại Trạng thái | F32: Trạng thái cập nhật thành "Chờ TBM xác nhận" sau khi refresh | H32: Untest
A33: TC-S04-24 | B33: SV chưa đăng ký đề tài | C33: - Đã đăng nhập - SV chưa đăng ký đề tài | D33: 1. Vào Đăng ký đề tài tốt nghiệp 2. Quan sát giao diện | F33: - Nút Đăng ký đề tài hiển thị - SV có thể thực hiện đăng ký | H33: Untest
A34: TC-S04-25 | B34: Kết quả tìm kiếm không hiển thị đề tài của SV khác | C34: - Đã đăng nhập SV Phạm Thị Nhung - SV Phạm Thị Nhung có đề tài mã E1, SV Nguyễn Thị Mỹ Phượng có đề tài mã Q1 | D34: 1. Tìm kiếm không nhập filter 2. Quan sát danh sách | F34: - Cột Trạng thái chỉ hiển thị trạng thái đề tài Mã Q1 - Đề tài mã E1 không có trạng thái đăng ký của SV khác | H34: Untest
A35: TC-S04-26 | B35: Truy cập trang khi chưa đăng nhập | C35: Chưa đăng nhập | D35: 1. Truy cập trực tiếp URL trang Đăng ký đề tài khi chưa login | E35: URL: http://14.241.80.87:9993/graduation/graduation-student-register-project-topic | F35: - Redirect về trang đăng nhập - Không hiển thị dữ liệu | H35: Pass
A36: UX/UI
A37: TC-S04-27 | B37: Load trang – hiển thị đủ các thành phần giao diện | C37: - Đã đăng nhập - SV đã đăng ký đề tài | D37: 1. Vào Đăng ký đề tài tốt nghiệp 2. Quan sát giao diện tổng thể | F37: Hiển thị đầy đủ: - Dropdown Mã Mã bộ môn - Dropdown Tên GV - Input Tên đề tài - Nút Tìm kiếm - Bảng danh sách đề tài | H37: Pass
A38: TC-S04-28 | B38: Bảng danh sách đề tài hiển thị đủ 9 cột đúng tên | C38: - Đã đăng nhập - Có kết quả tìm kiếm | D38: 1. Thực hiện tìm kiếm có kết quả 2. Quan sát tiêu đề bảng | F38: Bảng có đủ 9 cột: STT | Tên đề tài | Tên GV | Email | SĐT | Mô tả | Số SV đã ĐK GV này | Tác vụ | Trạng thái | H38: Pass
A39: TC-S04-29 | B39: Cột Trạng thái hiển thị đúng label theo từng trạng thái | C39: - Đã đăng nhập - SV đã đăng ký đề tài có trạng thái cụ thể | D39: 1. Tìm kiếm đề tài đã đăng ký 2. Quan sát cột Trạng thái | F39: Label hiển thị đúng 1 trong 4: "Chờ GV xác nhận" | "Chờ TBM xác nhận" | "Đã được duyệt" | "Từ chối" | H39: Pass
A40: TC-S04-30 | B40: SV chỉ thấy trạng thái đề tài của chính mình | C40: - Đã đăng nhập với tài khoản SV Phạm Thị Nhung - SV Phạm Thị Nhung và SV Vũ Thị Thùy Dương đều có đề tài | D40: 1. Tìm kiếm đề tài 2. Quan sát cột Trạng thái | F40: - Không hiển thị trạng thái đăng ký của SV Vũ Thị Thùy Dương - Chỉ thấy trạng thái đề tài của SV Phạm Thị Nhung | H40: Pass
A41: Exception
A42: TC-S04-31 | B42: Mất kết nối mạng khi nhấn Tìm kiếm | C42: - Đã đăng nhập - SV đã đăng ký đề tài | D42: 1. Điền thông tin tìm kiếm 2. Tắt mạng 3. Nhấn Tìm kiếm 4. Quan sát | F42: Hiển thị thông báo lỗi phù hợp | H42: Untest

Sheet 5. Xem quy trình hướng dẫn 
B2: Back to TestReport | C2: =HYPERLINK("#'Test case List'!A1","Test case List") -> Test case List | G2: Total | H2: =COUNTIF($A$10:$A$850, "TC*") -> 20
B3: Module Code | C3: Xem quy trình hướng dẫn | G3: Pass | H3: =(COUNTIF(H10:H34,"Pass")) -> 18
B4: Tester | C4: Vu Vy Thanh | G4: Fail | H4: =(COUNTIF(H10:H34,"Fail")) -> 0
G5: Untest | H5: =(COUNTIF(H10:H45,"Untest")) -> 2
B6: Percent Complete: | C6: =ROUND((H3 / (H2-H6))*100,2)&"%" -> 90% | G6: N/A | H6: =(COUNTIF(H10:H34,"N/A")) -> 0
A8: Test case ID | B8: Test Case Name | C8: Pre-Condition | D8: Test Case Steps | E8: Test Data | F8: Expected Output | G8: Bug ID | H8: Actual Result | I8: Note
A9: Functional TC
A10: TC-S05-01 | B10: Xem quy trình hướng dẫn thành công | C10: - Đã đăng nhập - SV có chuyên ngành Công nghệ phần mềm - Hệ thống đã có dữ liệu quy trình cho đợt + ngành | D10: 1. Vào Báo cáo kết quả ĐATN 2. Nhấn nút 'Quy trình hướng dẫn' 3. Quan sát modal Chi tiết quy trình | F10: - Modal Chi tiết quy trình mở ra - Bảng hiển thị đầy đủ cột: STT, Tuần, Công việc, Nội dung, Kết quả - Dữ liệu đúng theo ngành Công nghệ phần mềm và đợt hiện tại | H10: Pass
A11: TC-S05-02 | B11: Danh sách tuần hiển thị không lặp, đúng thứ tự tăng dần | C11: - Đã đăng nhập - Hệ thống có dữ liệu quy trình | D11: 1. Vào Báo cáo kết quả ĐATN 2. Nhấn 'Quy trình hướng dẫn' 3. Kiểm tra cột Tuần trong bảng | F11: - Cột Tuần không có giá trị trùng lặp - Thứ tự: Tuần 1 → Tuần 2 → ... → Tuần N (tăng dần) | H11: Pass | J11: M
A12: TC-S05-03 | B12: Quy trình hiển thị đúng theo chuyên ngành của SV | C12: - Có 2 tài khoản SV: ngành Công nghệ phần mềm và ngành Hệ thông thông tin - Mỗi ngành có quy trình riêng trong hệ thống | D12: 1. Đăng nhập SV ngành Công nghệ phần mềm 2. Xem quy trình → ghi nhận nội dung 3. Đăng xuất 4. Đăng nhập SV ngành Hệ thông thông tin 5. Xem quy trình → so sánh nội dung | F12: - Quy trình hiển thị khác nhau tương ứng với từng chuyên ngành - SV Công nghệ phần mềm không thấy quy trình của Hệ thông thông tin và ngược lại | H12: Pass
A13: TC-S05-04 | B13: SV chuyên ngành A không thấy quy trình chuyên ngành B | C13: - Có 2 tài khoản SV: ngành Công nghệ phần mềm và ngành Hệ thông thông tin - Mỗi ngành có quy trình riêng trong hệ thống | D13: 1. Đăng nhập SV ngành Công nghệ phần mềm 2. Quan sát quy trình hiển thị | F13: - Quy trình hiển thị khác nhau tương ứng với từng chuyên ngành - SV Công nghệ phần mềm không thấy quy trình của Hệ thông thông tin và ngược lại | H13: Pass | J13: M
A14: TC-S05-05 | B14: Quy trình hiển thị đúng theo đợt đồ án hiện tại | C14: Hệ thống có dữ liệu quy trình | D14: 1. Đăng nhập SV thuộc đợt đồ án hiện tại 2. Xem quy trình 3. Kiểm tra nội dung đúng đợt hiện tại | F14: Quy trình hiển thị là của Đợt mới nhất, không phải đợt cũ | H14: Pass | J14: M
A15: TC-S05-06 | B15: Không có dữ liệu quy trình cho ngành/đợt của SV | C15: - Đã đăng nhập - Hệ thống chưa cấu hình quy trình cho ngành/đợt của SV | D15: 1. Vào Báo cáo kết quả ĐATN 2. Nhấn 'Quy trình hướng dẫn' 3. Quan sát kết quả | F15: Hiển thị thông báo: 'Không tồn tại bản ghi nào.' | H15: Pass
A16: TC-S05-07 | B16: Sinh viên chưa đăng ký đề tài | C16: - Đã đăng nhập - Hệ thống có dữ liệu quy trình | D16: 1. Vào Báo cáo kết quả ĐATN 2. Nhấn 'Quy trình hướng dẫn' 3. Quan sát kết quả | F16: Hiển thị thông báo: 'Không tồn tại bản ghi nào.' | H16: Pass
A17: TC-S05-08 | B17: Truy cập trang khi chưa đăng nhập | C17: Chưa đăng nhập | D17: 1. Truy cập vào URL Báo cáo kết quả ĐATN khi chưa đăng nhập 2. Quan sát | E17: URL: http://14.241.80.87:9993/graduation/graduation-student-report-ref | F17: - Redirect về trang Đăng nhập - Không hiển thị dữ liệu | H17: Pass
A18: UX/UI
A19: TC-S05-09 | B19: Bảng Chi tiết có đủ 5 cột theo đặc tả | C19: - Đã đăng nhập - Hệ thống có dữ liệu quy trình | D19: 1. Mở modal Chi tiết quy trình 2. Kiểm tra header của bảng | F19: Bảng có đúng 5 cột theo thứ tự: STT | Tuần | Công việc | Nội dung | Kết quả | H19: Pass
A20: TC-S05-10 | B20: Cột STT đánh số đúng thứ tự liên tục | C20: - Đã đăng nhập - Có dữ liệu quy trình nhiều hàng | D20: 1. Mở modal Chi tiết quy trình 2. Kiểm tra cột STT | F20: Cột STT: 1, 2, 3, ..., N – liên tục, không lặp, không nhảy số | H20: Pass
A21: TC-S05-11 | B21: Nội dung từng tuần hiển thị đầy đủ, không bị cắt | C21: - Đã đăng nhập - Có dữ liệu quy trình với nội dung dài | D21: 1. Mở modal Chi tiết quy trình 2. Kiểm tra các ô có nội dung dài | F21: Hiển thị đầy đủ nội dung, không bị cắt '...' mất thông tin | H21: Pass
A22: TC-S05-12 | B22: Tên GVHD hiển thị đúng với đề tài đã đăng ký | C22: - Đã đăng nhập - SV đã có đề tài được duyệt với GVHD là 'Nguyễn Văn Đ' | D22: 1. Vào Báo cáo kết quả ĐATN 2. Kiểm tra Tên giảng viên hiển thị trên trang | F22: Tên giảng viên hiển thị đúng: 'Nguyễn Văn Đ' | H22: Pass
A23: TC-S05-13 | B23: Tên đề tài hiển thị đúng với đề tài đã đăng ký | C23: - Đã đăng nhập - SV đã có đề tài được duyệt | D23: 1. Vào Báo cáo kết quả ĐATN 2. Kiểm tra Tên đề tài hiển thị trên trang | F23: Tên đề tài hiển thị đúng khớp với đề tài đã được duyệt | H23: Pass
A24: TC-S05-14 | B24: Nút Quy trình hướng dẫn hiển thị đúng vị trí | C24: Đã đăng nhập | D24: 1. Vào Báo cáo kết quả ĐATN 2. Quan sát giao diện | F24: Nút 'Quy trình hướng dẫn' hiển thị rõ ràng, đúng vị trí trên trang | H24: Pass
A25: TC-S05-15 | B25: Đóng modal Chi tiết quy trình | C25: - Đã đăng nhập - Modal Chi tiết quy trình đang mở | D25: 1. Mở modal Chi tiết quy trình 2. Nhấn nút X hoặc click ra ngoài modal 3. Quan sát kết quả | F25: - Modal đóng lại - Trang chính không thay đổi - Không mất dữ liệu nào trên trang chính | H25: Pass
A26: TC-S05-16 | B26: Modal Chi tiết quy trình mở đúng khi nhấn nút | C26: - Đã đăng nhập - Hệ thống có dữ liệu quy trình | D26: 1. Nhấn nút 'Quy trình hướng dẫn' 2. Quan sát modal | F26: Modal mở ra đúng, hiển thị overlay, không bị vỡ layout | H26: Pass
A27: TC-S05-17 | B27: Bảng quy trình có scroll khi dữ liệu dài | C27: - Đã đăng nhập - Quy trình có nhiều tuần (>10 tuần) | D27: 1. Mở modal Chi tiết quy trình 2. Quan sát khả năng scroll | F27: Bảng có thể scroll, không bị tràn ra ngoài modal, không che mất nút đóng | H27: Pass
A28: TC-S05-18 | B28: Hiển thị đúng khi không có dữ liệu | C28: - Đã đăng nhập - Không có dữ liệu quy trình | D28: 1. Mở modal Chi tiết quy trình | F28: Hiển thị thông báo 'Không tồn tại bản ghi nào.' đúng vị trí, rõ ràng, không hiển thị bảng trống | H28: Pass
A29: Exception
A30: TC-S05-19 | B30: Mất mạng khi tải quy trình | C30: - Đã đăng nhập - Hệ thống có dữ liệu quy trình | D30: 1. Vào Báo cáo kết quả ĐATN 2. Tắt mạng 3. Nhấn 'Quy trình hướng dẫn' 4. Quan sát | F30: Hiển thị thông báo lỗi kết nối rõ ràng, không crash UI | H30: Untest
A31: TC-S05-20 | B31: SV thuộc ngành chưa được cấu hình quy trình | C31: - Đã đăng nhập - SV thuộc ngành X chưa có quy trình trong hệ thống | D31: 1. Vào Báo cáo kết quả ĐATN 2. Nhấn 'Quy trình hướng dẫn' 3. Quan sát | F31: Hiển thị thông báo "Không tồn tại bản ghi nào.", không báo lỗi hệ thống | H31: Untest

Sheet 6. Nộp báo cáo tuần
B2: Back to TestReport | C2: =HYPERLINK("#'Test case List'!A1","Test case List") -> Test case List | G2: Total | H2: =COUNTIF($A$10:$A$847, "TC*") -> 22
B3: Module Code | C3: Nộp báo cáo tuần | G3: Pass | H3: =(COUNTIF(H10:H33,"Pass")) -> 9
B4: Tester | C4: Vu Vy Thanh | G4: Fail | H4: =(COUNTIF(H10:H31,"Fail")) -> 0
G5: Untest | H5: =(COUNTIF(H10:H45,"Untest")) -> 13
B6: Percent Complete: | C6: =ROUND((H3 / (H2-H6))*100,2)&"%" -> 40.91% | G6: N/A | H6: =(COUNTIF(H10:H31,"N/A")) -> 0
A8: Test case ID | B8: Test Case Name | C8: Pre-Condition | D8: Test Case Steps | E8: Test Data | F8: Expected Output | G8: Bug ID | H8: Actual Result | I8: Note
A9: Functional TC
A10: TC-S06-01 | B10: Lưu báo cáo tuần thành công – có nội dung, không có link | C10: - Đã đăng nhập - Đề tài đã được duyệt - Danh sách tuần đã có trong hệ thống | D10: 1. Vào Báo cáo kết quả làm ĐATN 2. Nhấn Tác vụ tại Tuần 4 3. Nhập Nội dung báo cáo 4. Bỏ trống Link 5. Nhấn Lưu | E10: Nội dung: "Đã hoàn thành phân tích yêu cầu" Link: "" | F10: - Lưu thành công - Thông báo lưu thành công - Dữ liệu hiển thị trong bảng danh sách tuần | H10: Pass
A11: TC-S06-02 | B11: Lưu báo cáo tuần thành công – có nội dung và link hợp lệ | C11: - Đã đăng nhập - Đề tài đã được duyệt - Danh sách tuần đã có | D11: 1. Vào Báo cáo kết quả làm ĐATN 2. Nhấn Tác vụ tại Tuần 5 3. Nhập Nội dung 4. Nhập Link hợp lệ 5. Nhấn Lưu | E11: Nội dung: "Thiết kế database" Link: https://drive.google.com/file/abc | F11: - Lưu thành công - Link được lưu và hiển thị đúng trong cột Đường dẫn | H11: Pass
A12: TC-S06-03 | B12: Link đúng định dạng URL http:// | C12: - Đã đăng nhập - Đề tài đã được duyệt | D12: 1. Nhấn Tác vụ tại Tuần 4 2. Nhập nội dung và link 3. Nhấn Lưu | E12: Nội dung: "Báo cáo tuần 3" Link: http://example.com/report | F12: Lưu thành công, link được lưu đúng | H12: Untest
A13: TC-S06-04 | B13: Link đúng định dạng URL https:// | C13: - Đã đăng nhập - Đề tài đã được duyệt | D13: 1. Nhấn Tác vụ tại Tuần 6 2. Nhập nội dung và link https 3. Nhấn Lưu | E13: Link: https://drive.google.com/file/xyz | F13: Lưu thành công | H13: Untest
A14: TC-S06-05 | B14: Link thiếu giao thức (không có http/https) | C14: - Đã đăng nhập - Đề tài đã được duyệt | D14: 1. Nhấn Tác vụ tại Tuần 3 2. Nhập link không có http 3. Nhấn Lưu | E14: Link: drive.google.com/file/xyz | F14: Báo lỗi: "Link không đúng định dạng URL" Yêu cầu nhập lại | H14: Untest
A15: TC-S06-06 | B15: Link là chuỗi text thông thường (không phải URL) | C15: - Đã đăng nhập - Đề tài đã được duyệt | D15: 1. Nhấn Tác vụ tại Tuần X 2. Nhập link là text bình thường 3. Nhấn Lưu | E15: Link: "baocao tuan 3" | F15: Báo lỗi: "Link không đúng định dạng URL" | H15: Untest
A16: TC-S06-07 | B16: Link chứa khoảng trắng ở đầu/cuối | C16: - Đã đăng nhập - Đề tài đã được duyệt | D16: 1. Nhập link có khoảng trắng đầu cuối 2. Nhấn Lưu | E16: Link: " https://drive.google.com/file/abc " | F16: Báo lỗi: "Link không đúng định dạng URL" | H16: Untest
A17: TC-S06-08 | B17: Chỉ có 1 báo cáo mỗi tuần | C17: - Đã đăng nhập - Đề tài đã được duyệt - Tuần 3 đã có báo cáo lần 1 | D17: 1. Nhấn Tác vụ Tuần 3 2. Sửa nội dung 3. Nhấn Lưu 4. Kiểm tra dữ liệu | E17: Nội dung cũ: "Phân tích yêu cầu" Nội dung mới: "Phân tích và thiết kế" | F17: - Lưu thành công - Nội dung mới ghi đè nội dung cũ - Không tạo bản ghi trùng cho cùng tuần | H17: Untest
A18: TC-S06-09 | B18: Báo cáo tuần đúng tuần thuộc quy trình | C18: Đã đăng nhập Đề tài đã được duyệt Quy trình có Tuần 1 → 15 | D18: 1. Nhấn Tác vụ tại Tuần 1 2. Nhập nội dung hợp lệ 3. Nhấn Lưu | F18: Lưu thành công | H18: Untest
A19: TC-S06-10 | B19: TBM khoá tuần | C19: - Đã đăng nhập - Đề tài đã được duyệt - TBM đã khoá, chỉ cho phép báo cáo tuần hiện tại | D19: 1. Nhấn Tác vụ tại Tuần 3 (tuần cũ, đã khoá) 2. Thử nhập nội dung và Lưu | F19: Hệ thống từ chối Thông báo không thể báo cáo tuần này Nút Tác vụ bị disabled hoặc form không mở | H19: Untest
A20: TC-S06-11 | B20: SV chưa đăng ký đề tài | C20: - Đã đăng nhập - SV chưa đăng ký đề tài | D20: 1. Vào Báo cáo kết quả làm ĐATN 2. Quan sát danh sách tuần | F20: Hiển thị: "Không tồn tại bản ghi nào." hoặc thông báo yêu cầu đăng ký đề tài | H20: Untest
A21: TC-S06-12 | B21: Chưa có dữ liệu tuần trong hệ thống | C21: - Đã đăng nhập - Đề tài được duyệt | D21: 1. Vào Báo cáo kết quả làm ĐATN 2. Quan sát danh sách | F21: Hiển thị: "Không tồn tại bản ghi nào." | H21: Untest
A22: TC-S06-13 | B22: Báo cáo của SV A không ảnh hưởng dữ liệu SV B | C22: SV A và SV B đều đã đăng nhập và có đề tài | D22: 1. SV A lưu báo cáo Tuần 3 2. Kiểm tra DB báo cáo Tuần 3 của SV B | F22: Báo cáo Tuần 3 của SV B không bị thay đổi | H22: Untest
A23: TC-S06-14 | B23: Truy cập trang báo cáo tuần khi chưa đăng nhập | C23: Chưa đăng nhập | D23: 1. Truy cập trực tiếp URL trang Báo cáo kết quả khi chưa login | E23: URL: http://14.241.80.87:9993/graduation/graduation-student-report-ref | F23: Redirect về trang đăng nhập Không hiển thị dữ liệu | H23: Pass
A24: UX/UI
A25: TC-S06-15 | B25: Bảng danh sách tuần hiển thị đầy đủ 7 cột đúng tên | C25: - Đã đăng nhập - Đề tài được duyệt - Có dữ liệu tuần | D25: 1. Vào Báo cáo kết quả làm ĐATN 2. Quan sát tiêu đề bảng | F25: Bảng có đủ 7 cột: STT | Tuần | Nội dung thực hiện | Đường dẫn | Nhận xét | Điểm báo cáo tuần | Tác vụ | H25: Pass
A26: TC-S06-16 | B26: Danh sách tuần theo thứ tự tăng dần, không trùng | C26: - Đã đăng nhập - Có dữ liệu nhiều tuần | D26: 1. Vào Báo cáo kết quả làm ĐATN 2. Quan sát cột Tuần trong bảng | F26: - Bảng hiển thị: Tuần 1 → 2 → 3 → 4 (tăng dần) - Không có tuần trùng nhau | H26: Pass
A27: TC-S06-17 | B27: Nhấn Tác vụ cuộn lên form nhập báo cáo | C27: - Đã đăng nhập - Đề tài được duyệt - Danh sách tuần hiển thị | D27: 1. Nhấn nút Tác vụ tại Tuần 5 2. Quan sát form | F27: Form nhập báo cáo mở ra, hiển thị field Nội dung và field Link | H27: Pass
A28: TC-S06-18 | B28: Nội dung đã lưu hiển thị đúng trong bảng sau khi lưu | C28: Đã lưu báo cáo Tuần 5 thành công | D28: 1. Sau khi lưu thành công 2. Quan sát bảng danh sách tuần 3. Kiểm tra hàng Tuần 5 | E28: Nội dung đã lưu: "Hoàn thành chương 1" | F28: Cột Nội dung thực hiện tại Tuần 5 hiển thị đúng nội dung vừa lưu | H28: Pass
A29: TC-S06-19 | B29: Link đã lưu hiển thị đúng trong cột Đường dẫn | C29: Đã lưu báo cáo với link | D29: 1. Sau khi lưu thành công 2. Quan sát cột Đường dẫn tại Tuần 4 | E29: Link đã lưu: https://drive.google.com/drive/u/0/folders/1DUMbgDImjrSUzz8-vAA5WdExgSHRlusL | F29: Cột Đường dẫn hiển thị link đúng, có thể click | H29: Pass
A30: TC-S06-20 | B30: Thông báo lưu thành công hiển thị rõ ràng | C30: - Đã đăng nhập - Đề tài được duyệt | D30: 1. Điền nội dung hợp lệ 2. Nhấn Lưu 3. Quan sát thông báo | F30: Thông báo thành công hiển thị, nội dung rõ ràng | H30: Pass
A31: Exception
A32: TC-S06-21 | B32: Mất kết nối mạng khi nhấn Lưu | C32: - Đã đăng nhập - Đề tài được duyệt - Form đang mở | D32: 1. Nhập nội dung hợp lệ 2. Tắt mạng 3. Nhấn Lưu 4. Quan sát | F32: - Thông báo lỗi thất bại rõ ràng - Yêu cầu thử lại | H32: Untest
A33: TC-S06-22 | B33: Double click nút Lưu | C33: - Đã đăng nhập - Đề tài được duyệt - Form đã điền nội dung | D33: 1. Nhập nội dung hợp lệ 2. Click nút Lưu 2 lần liên tiếp nhanh 3. Quan sát giao diện | F33: - Chỉ lưu 1 bản ghi cho tuần đó - Không duplicate - Nút Lưu bị disabled sau click đầu tiên | H33: Untest

Sheet 7. Nộp BC cuối
B2: Back to TestReport | C2: =HYPERLINK("#'Test case List'!A1","Test case List") -> Test case List | G2: Total | H2: =COUNTIF($A$10:$A$846, "TC*") -> 20
B3: Module Code | C3: Nộp báo cáo cuối | G3: Pass | H3: =(COUNTIF(H10:H31,"Pass")) -> 6
B4: Tester | C4: Vu Vy Thanh | G4: Fail | H4: =(COUNTIF(H10:H31,"Fail")) -> 0
G5: Untest | H5: =(COUNTIF(H10:H31,"Untest")) -> 14
B6: Percent Complete: | C6: =ROUND((H3 / (H2-H6))*100,2)&"%" -> 30% | G6: N/A | H6: =(COUNTIF(H10:H31,"N/A")) -> 0
A8: Test case ID | B8: Test Case Name | C8: Pre-Condition | D8: Test Case Steps | E8: Test Data | F8: Expected Output | G8: Bug ID | H8: Actual Result | I8: Note
A9: Functional TC
A10: TC-S07-01 | B10: Nộp báo cáo cuối thành công – PDF hợp lệ < 30MB | C10: - Đã đăng nhập - Đề tài đã được duyệt - Đang trong thời gian cho phép nộp | D10: 1. Vào Báo cáo kết quả làm ĐATN 2. Nhấn Chọn tệp → chọn file PDF hợp lệ 3. Nhấn Lưu lại 4. Quan sát kết quả | E10: File: BaoCaoCuoi.pdf Dung lượng: 10MB | F10: - Thông báo nộp thành công - File được lưu vào hệ thống - Báo cáo được liên kết với đề tài của SV | H10: Untest
A11: TC-S07-02 | B11: Upload PDF đúng giới hạn 30MB | C11: - Đã đăng nhập - Đề tài đã được duyệt - Đang trong thời gian cho phép nộp | D11: 1. Chọn file PDF đúng 30MB 2. Nhấn Lưu lại 3. Quan sát kết quả | E11: File: Report_30MB.pdf Dung lượng: 30MB | F11: Upload và lưu thành công | H11: Untest
A12: TC-S07-03 | B12: Upload PDF vượt 30MB | C12: - Đã đăng nhập - Đề tài đã được duyệt - Đang trong thời gian cho phép nộp | D12: 1. Chọn file PDF > 30MB 2. Nhấn Lưu lại 3. Quan sát kết quả | E12: File: Report_35MB.pdf Dung lượng: 35MB | F12: Báo lỗi: "File vượt quá dung lượng cho phép (tối đa 30MB)" | H12: Untest
A13: TC-S07-04 | B13: Upload file không phải PDF (.docx) | C13: - Đã đăng nhập - Đề tài đã được duyệt - Đang trong thời gian cho phép nộp | D13: 1. Chọn file .docx 2. Nhấn Lưu lại 3. Quan sát kết quả | E13: File: BaoCao.docx | F13: Báo lỗi: "Chỉ chấp nhận file định dạng PDF" | H13: Untest
A14: TC-S07-05 | B14: Upload file rỗng | C14: - Đã đăng nhập - Đề tài đã được duyệt - Đang trong thời gian cho phép nộp | D14: 1. Tạo file PDF rỗng 0 byte 2. Upload file 3. Nhấn Lưu lại | E14: File: Empty.pdf Dung lượng: 0MB | F14: Báo lỗi: "File không hợp lệ hoặc rỗng" | H14: Untest
